[2025-02-21T13:57:41.935+0000] {taskinstance.py:1083} INFO - Dependencies all met for <TaskInstance: listenbrainz_dynamic_pipeline.process_file.load manual__2025-02-21T13:52:30.489409+00:00 map_index=1 [queued]>
[2025-02-21T13:57:41.946+0000] {taskinstance.py:1083} INFO - Dependencies all met for <TaskInstance: listenbrainz_dynamic_pipeline.process_file.load manual__2025-02-21T13:52:30.489409+00:00 map_index=1 [queued]>
[2025-02-21T13:57:41.947+0000] {taskinstance.py:1279} INFO - 
--------------------------------------------------------------------------------
[2025-02-21T13:57:41.947+0000] {taskinstance.py:1280} INFO - Starting attempt 1 of 2
[2025-02-21T13:57:41.947+0000] {taskinstance.py:1281} INFO - 
--------------------------------------------------------------------------------
[2025-02-21T13:57:41.961+0000] {taskinstance.py:1300} INFO - Executing <Task(_PythonDecoratedOperator): process_file.load> on 2025-02-21 13:52:30.489409+00:00
[2025-02-21T13:57:41.965+0000] {standard_task_runner.py:55} INFO - Started process 828 to run task
[2025-02-21T13:57:41.967+0000] {standard_task_runner.py:82} INFO - Running: ['***', 'tasks', 'run', 'listenbrainz_dynamic_pipeline', 'process_file.load', 'manual__2025-02-21T13:52:30.489409+00:00', '--job-id', '22', '--raw', '--subdir', 'DAGS_FOLDER/listenbrainz_dag.py', '--cfg-path', '/tmp/tmp9mqu3_lr', '--map-index', '1']
[2025-02-21T13:57:41.968+0000] {standard_task_runner.py:83} INFO - Job 22: Subtask process_file.load
[2025-02-21T13:57:42.035+0000] {task_command.py:388} INFO - Running <TaskInstance: listenbrainz_dynamic_pipeline.process_file.load manual__2025-02-21T13:52:30.489409+00:00 map_index=1 [running]> on host 930207e07779
[2025-02-21T13:57:42.104+0000] {taskinstance.py:1509} INFO - Exporting the following env vars:
AIRFLOW_CTX_DAG_OWNER=***
AIRFLOW_CTX_DAG_ID=listenbrainz_dynamic_pipeline
AIRFLOW_CTX_TASK_ID=process_file.load
AIRFLOW_CTX_EXECUTION_DATE=2025-02-21T13:52:30.489409+00:00
AIRFLOW_CTX_TRY_NUMBER=1
AIRFLOW_CTX_DAG_RUN_ID=manual__2025-02-21T13:52:30.489409+00:00
[2025-02-21T13:57:42.513+0000] {taskinstance.py:1768} ERROR - Task failed with exception
Traceback (most recent call last):
  File "/home/airflow/.local/lib/python3.7/site-packages/sqlalchemy/engine/base.py", line 3361, in _wrap_pool_connect
    return fn()
  File "/home/airflow/.local/lib/python3.7/site-packages/sqlalchemy/pool/base.py", line 327, in connect
    return _ConnectionFairy._checkout(self)
  File "/home/airflow/.local/lib/python3.7/site-packages/sqlalchemy/pool/base.py", line 894, in _checkout
    fairy = _ConnectionRecord.checkout(pool)
  File "/home/airflow/.local/lib/python3.7/site-packages/sqlalchemy/pool/base.py", line 493, in checkout
    rec = pool._do_get()
  File "/home/airflow/.local/lib/python3.7/site-packages/sqlalchemy/pool/impl.py", line 146, in _do_get
    self._dec_overflow()
  File "/home/airflow/.local/lib/python3.7/site-packages/sqlalchemy/util/langhelpers.py", line 72, in __exit__
    with_traceback=exc_tb,
  File "/home/airflow/.local/lib/python3.7/site-packages/sqlalchemy/util/compat.py", line 211, in raise_
    raise exception
  File "/home/airflow/.local/lib/python3.7/site-packages/sqlalchemy/pool/impl.py", line 143, in _do_get
    return self._create_connection()
  File "/home/airflow/.local/lib/python3.7/site-packages/sqlalchemy/pool/base.py", line 273, in _create_connection
    return _ConnectionRecord(self)
  File "/home/airflow/.local/lib/python3.7/site-packages/sqlalchemy/pool/base.py", line 388, in __init__
    self.__connect()
  File "/home/airflow/.local/lib/python3.7/site-packages/sqlalchemy/pool/base.py", line 691, in __connect
    pool.logger.debug("Error on connect(): %s", e)
  File "/home/airflow/.local/lib/python3.7/site-packages/sqlalchemy/util/langhelpers.py", line 72, in __exit__
    with_traceback=exc_tb,
  File "/home/airflow/.local/lib/python3.7/site-packages/sqlalchemy/util/compat.py", line 211, in raise_
    raise exception
  File "/home/airflow/.local/lib/python3.7/site-packages/sqlalchemy/pool/base.py", line 686, in __connect
    self.dbapi_connection = connection = pool._invoke_creator(self)
  File "/home/airflow/.local/lib/python3.7/site-packages/sqlalchemy/engine/create.py", line 578, in connect
    return dialect.connect(*cargs, **cparams)
  File "/home/airflow/.local/lib/python3.7/site-packages/duckdb_engine/__init__.py", line 282, in connect
    conn = duckdb.connect(*cargs, **cparams)
duckdb.duckdb.IOException: IO Error: Could not set lock on file "/data/listenbrainz.duckdb": Conflicting lock is held in /usr/local/bin/python3.7 (PID 743). See also https://duckdb.org/docs/connect/concurrency

The above exception was the direct cause of the following exception:

Traceback (most recent call last):
  File "/home/airflow/.local/lib/python3.7/site-packages/airflow/decorators/base.py", line 217, in execute
    return_value = super().execute(context)
  File "/home/airflow/.local/lib/python3.7/site-packages/airflow/operators/python.py", line 175, in execute
    return_value = self.execute_callable()
  File "/home/airflow/.local/lib/python3.7/site-packages/airflow/operators/python.py", line 192, in execute_callable
    return self.python_callable(*self.op_args, **self.op_kwargs)
  File "/opt/airflow/dags/listenbrainz_dag.py", line 87, in load_task
    load_csv_to_stg(engine, csv_path, "stg_listens", chunksize=50000)
  File "/opt/airflow/src/pipeline/unified_pipeline.py", line 121, in load_csv_to_stg
    chunk.to_sql(stg_table, db_engine, if_exists='replace', index=False)
  File "/home/airflow/.local/lib/python3.7/site-packages/pandas/core/generic.py", line 2882, in to_sql
    method=method,
  File "/home/airflow/.local/lib/python3.7/site-packages/pandas/io/sql.py", line 728, in to_sql
    **engine_kwargs,
  File "/home/airflow/.local/lib/python3.7/site-packages/pandas/io/sql.py", line 1758, in to_sql
    dtype=dtype,
  File "/home/airflow/.local/lib/python3.7/site-packages/pandas/io/sql.py", line 1650, in prep_table
    table.create()
  File "/home/airflow/.local/lib/python3.7/site-packages/pandas/io/sql.py", line 856, in create
    if self.exists():
  File "/home/airflow/.local/lib/python3.7/site-packages/pandas/io/sql.py", line 840, in exists
    return self.pd_sql.has_table(self.name, self.schema)
  File "/home/airflow/.local/lib/python3.7/site-packages/pandas/io/sql.py", line 1783, in has_table
    insp = sa.inspect(self.connectable)
  File "/home/airflow/.local/lib/python3.7/site-packages/sqlalchemy/inspection.py", line 64, in inspect
    ret = reg(subject)
  File "/home/airflow/.local/lib/python3.7/site-packages/sqlalchemy/engine/reflection.py", line 182, in _engine_insp
    return Inspector._construct(Inspector._init_engine, bind)
  File "/home/airflow/.local/lib/python3.7/site-packages/sqlalchemy/engine/reflection.py", line 117, in _construct
    init(self, bind)
  File "/home/airflow/.local/lib/python3.7/site-packages/sqlalchemy/engine/reflection.py", line 128, in _init_engine
    engine.connect().close()
  File "/home/airflow/.local/lib/python3.7/site-packages/sqlalchemy/future/engine.py", line 406, in connect
    return super(Engine, self).connect()
  File "/home/airflow/.local/lib/python3.7/site-packages/sqlalchemy/engine/base.py", line 3315, in connect
    return self._connection_cls(self, close_with_result=close_with_result)
  File "/home/airflow/.local/lib/python3.7/site-packages/sqlalchemy/engine/base.py", line 96, in __init__
    else engine.raw_connection()
  File "/home/airflow/.local/lib/python3.7/site-packages/sqlalchemy/engine/base.py", line 3394, in raw_connection
    return self._wrap_pool_connect(self.pool.connect, _connection)
  File "/home/airflow/.local/lib/python3.7/site-packages/sqlalchemy/engine/base.py", line 3365, in _wrap_pool_connect
    e, dialect, self
  File "/home/airflow/.local/lib/python3.7/site-packages/sqlalchemy/engine/base.py", line 2199, in _handle_dbapi_exception_noconnection
    sqlalchemy_exception, with_traceback=exc_info[2], from_=e
  File "/home/airflow/.local/lib/python3.7/site-packages/sqlalchemy/util/compat.py", line 211, in raise_
    raise exception
  File "/home/airflow/.local/lib/python3.7/site-packages/sqlalchemy/engine/base.py", line 3361, in _wrap_pool_connect
    return fn()
  File "/home/airflow/.local/lib/python3.7/site-packages/sqlalchemy/pool/base.py", line 327, in connect
    return _ConnectionFairy._checkout(self)
  File "/home/airflow/.local/lib/python3.7/site-packages/sqlalchemy/pool/base.py", line 894, in _checkout
    fairy = _ConnectionRecord.checkout(pool)
  File "/home/airflow/.local/lib/python3.7/site-packages/sqlalchemy/pool/base.py", line 493, in checkout
    rec = pool._do_get()
  File "/home/airflow/.local/lib/python3.7/site-packages/sqlalchemy/pool/impl.py", line 146, in _do_get
    self._dec_overflow()
  File "/home/airflow/.local/lib/python3.7/site-packages/sqlalchemy/util/langhelpers.py", line 72, in __exit__
    with_traceback=exc_tb,
  File "/home/airflow/.local/lib/python3.7/site-packages/sqlalchemy/util/compat.py", line 211, in raise_
    raise exception
  File "/home/airflow/.local/lib/python3.7/site-packages/sqlalchemy/pool/impl.py", line 143, in _do_get
    return self._create_connection()
  File "/home/airflow/.local/lib/python3.7/site-packages/sqlalchemy/pool/base.py", line 273, in _create_connection
    return _ConnectionRecord(self)
  File "/home/airflow/.local/lib/python3.7/site-packages/sqlalchemy/pool/base.py", line 388, in __init__
    self.__connect()
  File "/home/airflow/.local/lib/python3.7/site-packages/sqlalchemy/pool/base.py", line 691, in __connect
    pool.logger.debug("Error on connect(): %s", e)
  File "/home/airflow/.local/lib/python3.7/site-packages/sqlalchemy/util/langhelpers.py", line 72, in __exit__
    with_traceback=exc_tb,
  File "/home/airflow/.local/lib/python3.7/site-packages/sqlalchemy/util/compat.py", line 211, in raise_
    raise exception
  File "/home/airflow/.local/lib/python3.7/site-packages/sqlalchemy/pool/base.py", line 686, in __connect
    self.dbapi_connection = connection = pool._invoke_creator(self)
  File "/home/airflow/.local/lib/python3.7/site-packages/sqlalchemy/engine/create.py", line 578, in connect
    return dialect.connect(*cargs, **cparams)
  File "/home/airflow/.local/lib/python3.7/site-packages/duckdb_engine/__init__.py", line 282, in connect
    conn = duckdb.connect(*cargs, **cparams)
sqlalchemy.exc.OperationalError: (duckdb.duckdb.IOException) IO Error: Could not set lock on file "/data/listenbrainz.duckdb": Conflicting lock is held in /usr/local/bin/python3.7 (PID 743). See also https://duckdb.org/docs/connect/concurrency
(Background on this error at: https://sqlalche.me/e/14/e3q8)
[2025-02-21T13:57:42.526+0000] {taskinstance.py:1323} INFO - Marking task as UP_FOR_RETRY. dag_id=listenbrainz_dynamic_pipeline, task_id=process_file.load, map_index=1, execution_date=20250221T135230, start_date=20250221T135741, end_date=20250221T135742
[2025-02-21T13:57:42.541+0000] {standard_task_runner.py:105} ERROR - Failed to execute job 22 for task process_file.load ((duckdb.duckdb.IOException) IO Error: Could not set lock on file "/data/listenbrainz.duckdb": Conflicting lock is held in /usr/local/bin/python3.7 (PID 743). See also https://duckdb.org/docs/connect/concurrency
(Background on this error at: https://sqlalche.me/e/14/e3q8); 828)
[2025-02-21T13:57:42.579+0000] {local_task_job.py:208} INFO - Task exited with return code 1
[2025-02-21T13:57:42.622+0000] {taskinstance.py:2578} INFO - 0 downstream tasks scheduled from follow-on schedule check
