[2025-02-21T13:47:35.211+0000] {taskinstance.py:1083} INFO - Dependencies all met for <TaskInstance: listenbrainz_dynamic_pipeline.create_schema scheduled__2025-01-01T00:00:00+00:00 [queued]>
[2025-02-21T13:47:35.218+0000] {taskinstance.py:1083} INFO - Dependencies all met for <TaskInstance: listenbrainz_dynamic_pipeline.create_schema scheduled__2025-01-01T00:00:00+00:00 [queued]>
[2025-02-21T13:47:35.218+0000] {taskinstance.py:1279} INFO - 
--------------------------------------------------------------------------------
[2025-02-21T13:47:35.218+0000] {taskinstance.py:1280} INFO - Starting attempt 1 of 2
[2025-02-21T13:47:35.218+0000] {taskinstance.py:1281} INFO - 
--------------------------------------------------------------------------------
[2025-02-21T13:47:35.228+0000] {taskinstance.py:1300} INFO - Executing <Task(_PythonDecoratedOperator): create_schema> on 2025-01-01 00:00:00+00:00
[2025-02-21T13:47:35.231+0000] {standard_task_runner.py:55} INFO - Started process 185 to run task
[2025-02-21T13:47:35.233+0000] {standard_task_runner.py:82} INFO - Running: ['***', 'tasks', 'run', 'listenbrainz_dynamic_pipeline', 'create_schema', 'scheduled__2025-01-01T00:00:00+00:00', '--job-id', '3', '--raw', '--subdir', 'DAGS_FOLDER/listenbrainz_dag.py', '--cfg-path', '/tmp/tmpehhevic8']
[2025-02-21T13:47:35.234+0000] {standard_task_runner.py:83} INFO - Job 3: Subtask create_schema
[2025-02-21T13:47:35.286+0000] {task_command.py:388} INFO - Running <TaskInstance: listenbrainz_dynamic_pipeline.create_schema scheduled__2025-01-01T00:00:00+00:00 [running]> on host 930207e07779
[2025-02-21T13:47:35.347+0000] {taskinstance.py:1509} INFO - Exporting the following env vars:
AIRFLOW_CTX_DAG_OWNER=***
AIRFLOW_CTX_DAG_ID=listenbrainz_dynamic_pipeline
AIRFLOW_CTX_TASK_ID=create_schema
AIRFLOW_CTX_EXECUTION_DATE=2025-01-01T00:00:00+00:00
AIRFLOW_CTX_TRY_NUMBER=1
AIRFLOW_CTX_DAG_RUN_ID=scheduled__2025-01-01T00:00:00+00:00
[2025-02-21T13:47:35.409+0000] {taskinstance.py:1768} ERROR - Task failed with exception
Traceback (most recent call last):
  File "/home/airflow/.local/lib/python3.7/site-packages/sqlalchemy/engine/base.py", line 3361, in _wrap_pool_connect
    return fn()
  File "/home/airflow/.local/lib/python3.7/site-packages/sqlalchemy/pool/base.py", line 327, in connect
    return _ConnectionFairy._checkout(self)
  File "/home/airflow/.local/lib/python3.7/site-packages/sqlalchemy/pool/base.py", line 894, in _checkout
    fairy = _ConnectionRecord.checkout(pool)
  File "/home/airflow/.local/lib/python3.7/site-packages/sqlalchemy/pool/base.py", line 493, in checkout
    rec = pool._do_get()
  File "/home/airflow/.local/lib/python3.7/site-packages/sqlalchemy/pool/impl.py", line 146, in _do_get
    self._dec_overflow()
  File "/home/airflow/.local/lib/python3.7/site-packages/sqlalchemy/util/langhelpers.py", line 72, in __exit__
    with_traceback=exc_tb,
  File "/home/airflow/.local/lib/python3.7/site-packages/sqlalchemy/util/compat.py", line 211, in raise_
    raise exception
  File "/home/airflow/.local/lib/python3.7/site-packages/sqlalchemy/pool/impl.py", line 143, in _do_get
    return self._create_connection()
  File "/home/airflow/.local/lib/python3.7/site-packages/sqlalchemy/pool/base.py", line 273, in _create_connection
    return _ConnectionRecord(self)
  File "/home/airflow/.local/lib/python3.7/site-packages/sqlalchemy/pool/base.py", line 388, in __init__
    self.__connect()
  File "/home/airflow/.local/lib/python3.7/site-packages/sqlalchemy/pool/base.py", line 691, in __connect
    pool.logger.debug("Error on connect(): %s", e)
  File "/home/airflow/.local/lib/python3.7/site-packages/sqlalchemy/util/langhelpers.py", line 72, in __exit__
    with_traceback=exc_tb,
  File "/home/airflow/.local/lib/python3.7/site-packages/sqlalchemy/util/compat.py", line 211, in raise_
    raise exception
  File "/home/airflow/.local/lib/python3.7/site-packages/sqlalchemy/pool/base.py", line 686, in __connect
    self.dbapi_connection = connection = pool._invoke_creator(self)
  File "/home/airflow/.local/lib/python3.7/site-packages/sqlalchemy/engine/create.py", line 578, in connect
    return dialect.connect(*cargs, **cparams)
  File "/home/airflow/.local/lib/python3.7/site-packages/duckdb_engine/__init__.py", line 282, in connect
    conn = duckdb.connect(*cargs, **cparams)
duckdb.duckdb.IOException: IO Error: Could not set lock on file "/data/listenbrainz.duckdb": Conflicting lock is held in PID 0. See also https://duckdb.org/docs/connect/concurrency

The above exception was the direct cause of the following exception:

Traceback (most recent call last):
  File "/home/airflow/.local/lib/python3.7/site-packages/airflow/decorators/base.py", line 217, in execute
    return_value = super().execute(context)
  File "/home/airflow/.local/lib/python3.7/site-packages/airflow/operators/python.py", line 175, in execute
    return_value = self.execute_callable()
  File "/home/airflow/.local/lib/python3.7/site-packages/airflow/operators/python.py", line 192, in execute_callable
    return self.python_callable(*self.op_args, **self.op_kwargs)
  File "/opt/airflow/dags/listenbrainz_dag.py", line 58, in create_schema
    with engine.begin() as conn:
  File "/usr/local/lib/python3.7/contextlib.py", line 112, in __enter__
    return next(self.gen)
  File "/home/airflow/.local/lib/python3.7/site-packages/sqlalchemy/future/engine.py", line 379, in begin
    with self.connect() as conn:
  File "/home/airflow/.local/lib/python3.7/site-packages/sqlalchemy/future/engine.py", line 406, in connect
    return super(Engine, self).connect()
  File "/home/airflow/.local/lib/python3.7/site-packages/sqlalchemy/engine/base.py", line 3315, in connect
    return self._connection_cls(self, close_with_result=close_with_result)
  File "/home/airflow/.local/lib/python3.7/site-packages/sqlalchemy/engine/base.py", line 96, in __init__
    else engine.raw_connection()
  File "/home/airflow/.local/lib/python3.7/site-packages/sqlalchemy/engine/base.py", line 3394, in raw_connection
    return self._wrap_pool_connect(self.pool.connect, _connection)
  File "/home/airflow/.local/lib/python3.7/site-packages/sqlalchemy/engine/base.py", line 3365, in _wrap_pool_connect
    e, dialect, self
  File "/home/airflow/.local/lib/python3.7/site-packages/sqlalchemy/engine/base.py", line 2199, in _handle_dbapi_exception_noconnection
    sqlalchemy_exception, with_traceback=exc_info[2], from_=e
  File "/home/airflow/.local/lib/python3.7/site-packages/sqlalchemy/util/compat.py", line 211, in raise_
    raise exception
  File "/home/airflow/.local/lib/python3.7/site-packages/sqlalchemy/engine/base.py", line 3361, in _wrap_pool_connect
    return fn()
  File "/home/airflow/.local/lib/python3.7/site-packages/sqlalchemy/pool/base.py", line 327, in connect
    return _ConnectionFairy._checkout(self)
  File "/home/airflow/.local/lib/python3.7/site-packages/sqlalchemy/pool/base.py", line 894, in _checkout
    fairy = _ConnectionRecord.checkout(pool)
  File "/home/airflow/.local/lib/python3.7/site-packages/sqlalchemy/pool/base.py", line 493, in checkout
    rec = pool._do_get()
  File "/home/airflow/.local/lib/python3.7/site-packages/sqlalchemy/pool/impl.py", line 146, in _do_get
    self._dec_overflow()
  File "/home/airflow/.local/lib/python3.7/site-packages/sqlalchemy/util/langhelpers.py", line 72, in __exit__
    with_traceback=exc_tb,
  File "/home/airflow/.local/lib/python3.7/site-packages/sqlalchemy/util/compat.py", line 211, in raise_
    raise exception
  File "/home/airflow/.local/lib/python3.7/site-packages/sqlalchemy/pool/impl.py", line 143, in _do_get
    return self._create_connection()
  File "/home/airflow/.local/lib/python3.7/site-packages/sqlalchemy/pool/base.py", line 273, in _create_connection
    return _ConnectionRecord(self)
  File "/home/airflow/.local/lib/python3.7/site-packages/sqlalchemy/pool/base.py", line 388, in __init__
    self.__connect()
  File "/home/airflow/.local/lib/python3.7/site-packages/sqlalchemy/pool/base.py", line 691, in __connect
    pool.logger.debug("Error on connect(): %s", e)
  File "/home/airflow/.local/lib/python3.7/site-packages/sqlalchemy/util/langhelpers.py", line 72, in __exit__
    with_traceback=exc_tb,
  File "/home/airflow/.local/lib/python3.7/site-packages/sqlalchemy/util/compat.py", line 211, in raise_
    raise exception
  File "/home/airflow/.local/lib/python3.7/site-packages/sqlalchemy/pool/base.py", line 686, in __connect
    self.dbapi_connection = connection = pool._invoke_creator(self)
  File "/home/airflow/.local/lib/python3.7/site-packages/sqlalchemy/engine/create.py", line 578, in connect
    return dialect.connect(*cargs, **cparams)
  File "/home/airflow/.local/lib/python3.7/site-packages/duckdb_engine/__init__.py", line 282, in connect
    conn = duckdb.connect(*cargs, **cparams)
sqlalchemy.exc.OperationalError: (duckdb.duckdb.IOException) IO Error: Could not set lock on file "/data/listenbrainz.duckdb": Conflicting lock is held in PID 0. See also https://duckdb.org/docs/connect/concurrency
(Background on this error at: https://sqlalche.me/e/14/e3q8)
[2025-02-21T13:47:35.420+0000] {taskinstance.py:1323} INFO - Marking task as UP_FOR_RETRY. dag_id=listenbrainz_dynamic_pipeline, task_id=create_schema, execution_date=20250101T000000, start_date=20250221T134735, end_date=20250221T134735
[2025-02-21T13:47:35.429+0000] {standard_task_runner.py:105} ERROR - Failed to execute job 3 for task create_schema ((duckdb.duckdb.IOException) IO Error: Could not set lock on file "/data/listenbrainz.duckdb": Conflicting lock is held in PID 0. See also https://duckdb.org/docs/connect/concurrency
(Background on this error at: https://sqlalche.me/e/14/e3q8); 185)
[2025-02-21T13:47:35.445+0000] {local_task_job.py:208} INFO - Task exited with return code 1
[2025-02-21T13:47:35.476+0000] {taskinstance.py:2578} INFO - 0 downstream tasks scheduled from follow-on schedule check
[2025-02-21T13:52:35.826+0000] {taskinstance.py:1083} INFO - Dependencies all met for <TaskInstance: listenbrainz_dynamic_pipeline.create_schema scheduled__2025-01-01T00:00:00+00:00 [queued]>
[2025-02-21T13:52:35.832+0000] {taskinstance.py:1083} INFO - Dependencies all met for <TaskInstance: listenbrainz_dynamic_pipeline.create_schema scheduled__2025-01-01T00:00:00+00:00 [queued]>
[2025-02-21T13:52:35.832+0000] {taskinstance.py:1279} INFO - 
--------------------------------------------------------------------------------
[2025-02-21T13:52:35.832+0000] {taskinstance.py:1280} INFO - Starting attempt 1 of 2
[2025-02-21T13:52:35.832+0000] {taskinstance.py:1281} INFO - 
--------------------------------------------------------------------------------
[2025-02-21T13:52:35.842+0000] {taskinstance.py:1300} INFO - Executing <Task(_PythonDecoratedOperator): create_schema> on 2025-01-01 00:00:00+00:00
[2025-02-21T13:52:35.845+0000] {standard_task_runner.py:55} INFO - Started process 331 to run task
[2025-02-21T13:52:35.847+0000] {standard_task_runner.py:82} INFO - Running: ['***', 'tasks', 'run', 'listenbrainz_dynamic_pipeline', 'create_schema', 'scheduled__2025-01-01T00:00:00+00:00', '--job-id', '6', '--raw', '--subdir', 'DAGS_FOLDER/listenbrainz_dag.py', '--cfg-path', '/tmp/tmpv_s452mb']
[2025-02-21T13:52:35.848+0000] {standard_task_runner.py:83} INFO - Job 6: Subtask create_schema
[2025-02-21T13:52:35.896+0000] {task_command.py:388} INFO - Running <TaskInstance: listenbrainz_dynamic_pipeline.create_schema scheduled__2025-01-01T00:00:00+00:00 [running]> on host 930207e07779
[2025-02-21T13:52:35.951+0000] {taskinstance.py:1509} INFO - Exporting the following env vars:
AIRFLOW_CTX_DAG_OWNER=***
AIRFLOW_CTX_DAG_ID=listenbrainz_dynamic_pipeline
AIRFLOW_CTX_TASK_ID=create_schema
AIRFLOW_CTX_EXECUTION_DATE=2025-01-01T00:00:00+00:00
AIRFLOW_CTX_TRY_NUMBER=1
AIRFLOW_CTX_DAG_RUN_ID=scheduled__2025-01-01T00:00:00+00:00
[2025-02-21T13:52:36.008+0000] {taskinstance.py:1768} ERROR - Task failed with exception
Traceback (most recent call last):
  File "/home/airflow/.local/lib/python3.7/site-packages/sqlalchemy/engine/base.py", line 3361, in _wrap_pool_connect
    return fn()
  File "/home/airflow/.local/lib/python3.7/site-packages/sqlalchemy/pool/base.py", line 327, in connect
    return _ConnectionFairy._checkout(self)
  File "/home/airflow/.local/lib/python3.7/site-packages/sqlalchemy/pool/base.py", line 894, in _checkout
    fairy = _ConnectionRecord.checkout(pool)
  File "/home/airflow/.local/lib/python3.7/site-packages/sqlalchemy/pool/base.py", line 493, in checkout
    rec = pool._do_get()
  File "/home/airflow/.local/lib/python3.7/site-packages/sqlalchemy/pool/impl.py", line 146, in _do_get
    self._dec_overflow()
  File "/home/airflow/.local/lib/python3.7/site-packages/sqlalchemy/util/langhelpers.py", line 72, in __exit__
    with_traceback=exc_tb,
  File "/home/airflow/.local/lib/python3.7/site-packages/sqlalchemy/util/compat.py", line 211, in raise_
    raise exception
  File "/home/airflow/.local/lib/python3.7/site-packages/sqlalchemy/pool/impl.py", line 143, in _do_get
    return self._create_connection()
  File "/home/airflow/.local/lib/python3.7/site-packages/sqlalchemy/pool/base.py", line 273, in _create_connection
    return _ConnectionRecord(self)
  File "/home/airflow/.local/lib/python3.7/site-packages/sqlalchemy/pool/base.py", line 388, in __init__
    self.__connect()
  File "/home/airflow/.local/lib/python3.7/site-packages/sqlalchemy/pool/base.py", line 691, in __connect
    pool.logger.debug("Error on connect(): %s", e)
  File "/home/airflow/.local/lib/python3.7/site-packages/sqlalchemy/util/langhelpers.py", line 72, in __exit__
    with_traceback=exc_tb,
  File "/home/airflow/.local/lib/python3.7/site-packages/sqlalchemy/util/compat.py", line 211, in raise_
    raise exception
  File "/home/airflow/.local/lib/python3.7/site-packages/sqlalchemy/pool/base.py", line 686, in __connect
    self.dbapi_connection = connection = pool._invoke_creator(self)
  File "/home/airflow/.local/lib/python3.7/site-packages/sqlalchemy/engine/create.py", line 578, in connect
    return dialect.connect(*cargs, **cparams)
  File "/home/airflow/.local/lib/python3.7/site-packages/duckdb_engine/__init__.py", line 282, in connect
    conn = duckdb.connect(*cargs, **cparams)
duckdb.duckdb.IOException: IO Error: Could not set lock on file "/data/listenbrainz.duckdb": Conflicting lock is held in PID 0. See also https://duckdb.org/docs/connect/concurrency

The above exception was the direct cause of the following exception:

Traceback (most recent call last):
  File "/home/airflow/.local/lib/python3.7/site-packages/airflow/decorators/base.py", line 217, in execute
    return_value = super().execute(context)
  File "/home/airflow/.local/lib/python3.7/site-packages/airflow/operators/python.py", line 175, in execute
    return_value = self.execute_callable()
  File "/home/airflow/.local/lib/python3.7/site-packages/airflow/operators/python.py", line 192, in execute_callable
    return self.python_callable(*self.op_args, **self.op_kwargs)
  File "/opt/airflow/dags/listenbrainz_dag.py", line 58, in create_schema
    with engine.begin() as conn:
  File "/usr/local/lib/python3.7/contextlib.py", line 112, in __enter__
    return next(self.gen)
  File "/home/airflow/.local/lib/python3.7/site-packages/sqlalchemy/future/engine.py", line 379, in begin
    with self.connect() as conn:
  File "/home/airflow/.local/lib/python3.7/site-packages/sqlalchemy/future/engine.py", line 406, in connect
    return super(Engine, self).connect()
  File "/home/airflow/.local/lib/python3.7/site-packages/sqlalchemy/engine/base.py", line 3315, in connect
    return self._connection_cls(self, close_with_result=close_with_result)
  File "/home/airflow/.local/lib/python3.7/site-packages/sqlalchemy/engine/base.py", line 96, in __init__
    else engine.raw_connection()
  File "/home/airflow/.local/lib/python3.7/site-packages/sqlalchemy/engine/base.py", line 3394, in raw_connection
    return self._wrap_pool_connect(self.pool.connect, _connection)
  File "/home/airflow/.local/lib/python3.7/site-packages/sqlalchemy/engine/base.py", line 3365, in _wrap_pool_connect
    e, dialect, self
  File "/home/airflow/.local/lib/python3.7/site-packages/sqlalchemy/engine/base.py", line 2199, in _handle_dbapi_exception_noconnection
    sqlalchemy_exception, with_traceback=exc_info[2], from_=e
  File "/home/airflow/.local/lib/python3.7/site-packages/sqlalchemy/util/compat.py", line 211, in raise_
    raise exception
  File "/home/airflow/.local/lib/python3.7/site-packages/sqlalchemy/engine/base.py", line 3361, in _wrap_pool_connect
    return fn()
  File "/home/airflow/.local/lib/python3.7/site-packages/sqlalchemy/pool/base.py", line 327, in connect
    return _ConnectionFairy._checkout(self)
  File "/home/airflow/.local/lib/python3.7/site-packages/sqlalchemy/pool/base.py", line 894, in _checkout
    fairy = _ConnectionRecord.checkout(pool)
  File "/home/airflow/.local/lib/python3.7/site-packages/sqlalchemy/pool/base.py", line 493, in checkout
    rec = pool._do_get()
  File "/home/airflow/.local/lib/python3.7/site-packages/sqlalchemy/pool/impl.py", line 146, in _do_get
    self._dec_overflow()
  File "/home/airflow/.local/lib/python3.7/site-packages/sqlalchemy/util/langhelpers.py", line 72, in __exit__
    with_traceback=exc_tb,
  File "/home/airflow/.local/lib/python3.7/site-packages/sqlalchemy/util/compat.py", line 211, in raise_
    raise exception
  File "/home/airflow/.local/lib/python3.7/site-packages/sqlalchemy/pool/impl.py", line 143, in _do_get
    return self._create_connection()
  File "/home/airflow/.local/lib/python3.7/site-packages/sqlalchemy/pool/base.py", line 273, in _create_connection
    return _ConnectionRecord(self)
  File "/home/airflow/.local/lib/python3.7/site-packages/sqlalchemy/pool/base.py", line 388, in __init__
    self.__connect()
  File "/home/airflow/.local/lib/python3.7/site-packages/sqlalchemy/pool/base.py", line 691, in __connect
    pool.logger.debug("Error on connect(): %s", e)
  File "/home/airflow/.local/lib/python3.7/site-packages/sqlalchemy/util/langhelpers.py", line 72, in __exit__
    with_traceback=exc_tb,
  File "/home/airflow/.local/lib/python3.7/site-packages/sqlalchemy/util/compat.py", line 211, in raise_
    raise exception
  File "/home/airflow/.local/lib/python3.7/site-packages/sqlalchemy/pool/base.py", line 686, in __connect
    self.dbapi_connection = connection = pool._invoke_creator(self)
  File "/home/airflow/.local/lib/python3.7/site-packages/sqlalchemy/engine/create.py", line 578, in connect
    return dialect.connect(*cargs, **cparams)
  File "/home/airflow/.local/lib/python3.7/site-packages/duckdb_engine/__init__.py", line 282, in connect
    conn = duckdb.connect(*cargs, **cparams)
sqlalchemy.exc.OperationalError: (duckdb.duckdb.IOException) IO Error: Could not set lock on file "/data/listenbrainz.duckdb": Conflicting lock is held in PID 0. See also https://duckdb.org/docs/connect/concurrency
(Background on this error at: https://sqlalche.me/e/14/e3q8)
[2025-02-21T13:52:36.019+0000] {taskinstance.py:1323} INFO - Marking task as UP_FOR_RETRY. dag_id=listenbrainz_dynamic_pipeline, task_id=create_schema, execution_date=20250101T000000, start_date=20250221T135235, end_date=20250221T135236
[2025-02-21T13:52:36.026+0000] {standard_task_runner.py:105} ERROR - Failed to execute job 6 for task create_schema ((duckdb.duckdb.IOException) IO Error: Could not set lock on file "/data/listenbrainz.duckdb": Conflicting lock is held in PID 0. See also https://duckdb.org/docs/connect/concurrency
(Background on this error at: https://sqlalche.me/e/14/e3q8); 331)
[2025-02-21T13:52:36.059+0000] {local_task_job.py:208} INFO - Task exited with return code 1
[2025-02-21T13:52:36.088+0000] {taskinstance.py:2578} INFO - 0 downstream tasks scheduled from follow-on schedule check
[2025-02-21T13:59:37.271+0000] {taskinstance.py:1083} INFO - Dependencies all met for <TaskInstance: listenbrainz_dynamic_pipeline.create_schema scheduled__2025-01-01T00:00:00+00:00 [queued]>
[2025-02-21T13:59:37.277+0000] {taskinstance.py:1083} INFO - Dependencies all met for <TaskInstance: listenbrainz_dynamic_pipeline.create_schema scheduled__2025-01-01T00:00:00+00:00 [queued]>
[2025-02-21T13:59:37.277+0000] {taskinstance.py:1279} INFO - 
--------------------------------------------------------------------------------
[2025-02-21T13:59:37.277+0000] {taskinstance.py:1280} INFO - Starting attempt 1 of 2
[2025-02-21T13:59:37.278+0000] {taskinstance.py:1281} INFO - 
--------------------------------------------------------------------------------
[2025-02-21T13:59:37.287+0000] {taskinstance.py:1300} INFO - Executing <Task(_PythonDecoratedOperator): create_schema> on 2025-01-01 00:00:00+00:00
[2025-02-21T13:59:37.291+0000] {standard_task_runner.py:55} INFO - Started process 185 to run task
[2025-02-21T13:59:37.292+0000] {standard_task_runner.py:82} INFO - Running: ['***', 'tasks', 'run', 'listenbrainz_dynamic_pipeline', 'create_schema', 'scheduled__2025-01-01T00:00:00+00:00', '--job-id', '3', '--raw', '--subdir', 'DAGS_FOLDER/listenbrainz_dag.py', '--cfg-path', '/tmp/tmpbkwey0b8']
[2025-02-21T13:59:37.293+0000] {standard_task_runner.py:83} INFO - Job 3: Subtask create_schema
[2025-02-21T13:59:37.344+0000] {task_command.py:388} INFO - Running <TaskInstance: listenbrainz_dynamic_pipeline.create_schema scheduled__2025-01-01T00:00:00+00:00 [running]> on host ab567731ea96
[2025-02-21T13:59:37.409+0000] {taskinstance.py:1509} INFO - Exporting the following env vars:
AIRFLOW_CTX_DAG_OWNER=***
AIRFLOW_CTX_DAG_ID=listenbrainz_dynamic_pipeline
AIRFLOW_CTX_TASK_ID=create_schema
AIRFLOW_CTX_EXECUTION_DATE=2025-01-01T00:00:00+00:00
AIRFLOW_CTX_TRY_NUMBER=1
AIRFLOW_CTX_DAG_RUN_ID=scheduled__2025-01-01T00:00:00+00:00
[2025-02-21T13:59:37.480+0000] {listenbrainz_dag.py:61} INFO - Schema created/ensured.
[2025-02-21T13:59:37.480+0000] {python.py:177} INFO - Done. Returned value was: None
[2025-02-21T13:59:37.491+0000] {taskinstance.py:1323} INFO - Marking task as SUCCESS. dag_id=listenbrainz_dynamic_pipeline, task_id=create_schema, execution_date=20250101T000000, start_date=20250221T135937, end_date=20250221T135937
[2025-02-21T13:59:37.544+0000] {local_task_job.py:208} INFO - Task exited with return code 0
[2025-02-21T13:59:37.593+0000] {taskinstance.py:2578} INFO - 1 downstream tasks scheduled from follow-on schedule check
[2025-02-21T14:04:55.148+0000] {taskinstance.py:1083} INFO - Dependencies all met for <TaskInstance: listenbrainz_dynamic_pipeline.create_schema scheduled__2025-01-01T00:00:00+00:00 [queued]>
[2025-02-21T14:04:55.155+0000] {taskinstance.py:1083} INFO - Dependencies all met for <TaskInstance: listenbrainz_dynamic_pipeline.create_schema scheduled__2025-01-01T00:00:00+00:00 [queued]>
[2025-02-21T14:04:55.155+0000] {taskinstance.py:1279} INFO - 
--------------------------------------------------------------------------------
[2025-02-21T14:04:55.155+0000] {taskinstance.py:1280} INFO - Starting attempt 1 of 2
[2025-02-21T14:04:55.155+0000] {taskinstance.py:1281} INFO - 
--------------------------------------------------------------------------------
[2025-02-21T14:04:55.165+0000] {taskinstance.py:1300} INFO - Executing <Task(_PythonDecoratedOperator): create_schema> on 2025-01-01 00:00:00+00:00
[2025-02-21T14:04:55.169+0000] {standard_task_runner.py:55} INFO - Started process 185 to run task
[2025-02-21T14:04:55.170+0000] {standard_task_runner.py:82} INFO - Running: ['***', 'tasks', 'run', 'listenbrainz_dynamic_pipeline', 'create_schema', 'scheduled__2025-01-01T00:00:00+00:00', '--job-id', '3', '--raw', '--subdir', 'DAGS_FOLDER/listenbrainz_dag.py', '--cfg-path', '/tmp/tmp3x0dxa4g']
[2025-02-21T14:04:55.171+0000] {standard_task_runner.py:83} INFO - Job 3: Subtask create_schema
[2025-02-21T14:04:55.222+0000] {task_command.py:388} INFO - Running <TaskInstance: listenbrainz_dynamic_pipeline.create_schema scheduled__2025-01-01T00:00:00+00:00 [running]> on host 5b6f74597018
[2025-02-21T14:04:55.282+0000] {taskinstance.py:1509} INFO - Exporting the following env vars:
AIRFLOW_CTX_DAG_OWNER=***
AIRFLOW_CTX_DAG_ID=listenbrainz_dynamic_pipeline
AIRFLOW_CTX_TASK_ID=create_schema
AIRFLOW_CTX_EXECUTION_DATE=2025-01-01T00:00:00+00:00
AIRFLOW_CTX_TRY_NUMBER=1
AIRFLOW_CTX_DAG_RUN_ID=scheduled__2025-01-01T00:00:00+00:00
[2025-02-21T14:04:55.350+0000] {listenbrainz_dag.py:61} INFO - Schema created/ensured.
[2025-02-21T14:04:55.350+0000] {python.py:177} INFO - Done. Returned value was: None
[2025-02-21T14:04:55.360+0000] {taskinstance.py:1323} INFO - Marking task as SUCCESS. dag_id=listenbrainz_dynamic_pipeline, task_id=create_schema, execution_date=20250101T000000, start_date=20250221T140455, end_date=20250221T140455
[2025-02-21T14:04:55.382+0000] {local_task_job.py:208} INFO - Task exited with return code 0
[2025-02-21T14:04:55.414+0000] {taskinstance.py:2578} INFO - 1 downstream tasks scheduled from follow-on schedule check
[2025-02-21T14:24:15.231+0000] {taskinstance.py:1083} INFO - Dependencies all met for <TaskInstance: listenbrainz_dynamic_pipeline.create_schema scheduled__2025-01-01T00:00:00+00:00 [queued]>
[2025-02-21T14:24:15.238+0000] {taskinstance.py:1083} INFO - Dependencies all met for <TaskInstance: listenbrainz_dynamic_pipeline.create_schema scheduled__2025-01-01T00:00:00+00:00 [queued]>
[2025-02-21T14:24:15.238+0000] {taskinstance.py:1279} INFO - 
--------------------------------------------------------------------------------
[2025-02-21T14:24:15.238+0000] {taskinstance.py:1280} INFO - Starting attempt 1 of 2
[2025-02-21T14:24:15.238+0000] {taskinstance.py:1281} INFO - 
--------------------------------------------------------------------------------
[2025-02-21T14:24:15.248+0000] {taskinstance.py:1300} INFO - Executing <Task(_PythonDecoratedOperator): create_schema> on 2025-01-01 00:00:00+00:00
[2025-02-21T14:24:15.252+0000] {standard_task_runner.py:55} INFO - Started process 185 to run task
[2025-02-21T14:24:15.253+0000] {standard_task_runner.py:82} INFO - Running: ['***', 'tasks', 'run', 'listenbrainz_dynamic_pipeline', 'create_schema', 'scheduled__2025-01-01T00:00:00+00:00', '--job-id', '3', '--raw', '--subdir', 'DAGS_FOLDER/listenbrainz_dag.py', '--cfg-path', '/tmp/tmpozoxxlel']
[2025-02-21T14:24:15.254+0000] {standard_task_runner.py:83} INFO - Job 3: Subtask create_schema
[2025-02-21T14:24:15.305+0000] {task_command.py:388} INFO - Running <TaskInstance: listenbrainz_dynamic_pipeline.create_schema scheduled__2025-01-01T00:00:00+00:00 [running]> on host 67bebaff4560
[2025-02-21T14:24:15.364+0000] {taskinstance.py:1509} INFO - Exporting the following env vars:
AIRFLOW_CTX_DAG_OWNER=***
AIRFLOW_CTX_DAG_ID=listenbrainz_dynamic_pipeline
AIRFLOW_CTX_TASK_ID=create_schema
AIRFLOW_CTX_EXECUTION_DATE=2025-01-01T00:00:00+00:00
AIRFLOW_CTX_TRY_NUMBER=1
AIRFLOW_CTX_DAG_RUN_ID=scheduled__2025-01-01T00:00:00+00:00
[2025-02-21T14:24:15.424+0000] {taskinstance.py:1768} ERROR - Task failed with exception
Traceback (most recent call last):
  File "/home/airflow/.local/lib/python3.7/site-packages/sqlalchemy/engine/base.py", line 3361, in _wrap_pool_connect
    return fn()
  File "/home/airflow/.local/lib/python3.7/site-packages/sqlalchemy/pool/base.py", line 327, in connect
    return _ConnectionFairy._checkout(self)
  File "/home/airflow/.local/lib/python3.7/site-packages/sqlalchemy/pool/base.py", line 894, in _checkout
    fairy = _ConnectionRecord.checkout(pool)
  File "/home/airflow/.local/lib/python3.7/site-packages/sqlalchemy/pool/base.py", line 493, in checkout
    rec = pool._do_get()
  File "/home/airflow/.local/lib/python3.7/site-packages/sqlalchemy/pool/impl.py", line 146, in _do_get
    self._dec_overflow()
  File "/home/airflow/.local/lib/python3.7/site-packages/sqlalchemy/util/langhelpers.py", line 72, in __exit__
    with_traceback=exc_tb,
  File "/home/airflow/.local/lib/python3.7/site-packages/sqlalchemy/util/compat.py", line 211, in raise_
    raise exception
  File "/home/airflow/.local/lib/python3.7/site-packages/sqlalchemy/pool/impl.py", line 143, in _do_get
    return self._create_connection()
  File "/home/airflow/.local/lib/python3.7/site-packages/sqlalchemy/pool/base.py", line 273, in _create_connection
    return _ConnectionRecord(self)
  File "/home/airflow/.local/lib/python3.7/site-packages/sqlalchemy/pool/base.py", line 388, in __init__
    self.__connect()
  File "/home/airflow/.local/lib/python3.7/site-packages/sqlalchemy/pool/base.py", line 691, in __connect
    pool.logger.debug("Error on connect(): %s", e)
  File "/home/airflow/.local/lib/python3.7/site-packages/sqlalchemy/util/langhelpers.py", line 72, in __exit__
    with_traceback=exc_tb,
  File "/home/airflow/.local/lib/python3.7/site-packages/sqlalchemy/util/compat.py", line 211, in raise_
    raise exception
  File "/home/airflow/.local/lib/python3.7/site-packages/sqlalchemy/pool/base.py", line 686, in __connect
    self.dbapi_connection = connection = pool._invoke_creator(self)
  File "/home/airflow/.local/lib/python3.7/site-packages/sqlalchemy/engine/create.py", line 578, in connect
    return dialect.connect(*cargs, **cparams)
  File "/home/airflow/.local/lib/python3.7/site-packages/duckdb_engine/__init__.py", line 282, in connect
    conn = duckdb.connect(*cargs, **cparams)
duckdb.duckdb.IOException: IO Error: Could not set lock on file "/data/listenbrainz.duckdb": Conflicting lock is held in PID 0. See also https://duckdb.org/docs/connect/concurrency

The above exception was the direct cause of the following exception:

Traceback (most recent call last):
  File "/home/airflow/.local/lib/python3.7/site-packages/airflow/decorators/base.py", line 217, in execute
    return_value = super().execute(context)
  File "/home/airflow/.local/lib/python3.7/site-packages/airflow/operators/python.py", line 175, in execute
    return_value = self.execute_callable()
  File "/home/airflow/.local/lib/python3.7/site-packages/airflow/operators/python.py", line 192, in execute_callable
    return self.python_callable(*self.op_args, **self.op_kwargs)
  File "/opt/airflow/dags/listenbrainz_dag.py", line 54, in create_schema
    with engine.begin() as conn:
  File "/usr/local/lib/python3.7/contextlib.py", line 112, in __enter__
    return next(self.gen)
  File "/home/airflow/.local/lib/python3.7/site-packages/sqlalchemy/future/engine.py", line 379, in begin
    with self.connect() as conn:
  File "/home/airflow/.local/lib/python3.7/site-packages/sqlalchemy/future/engine.py", line 406, in connect
    return super(Engine, self).connect()
  File "/home/airflow/.local/lib/python3.7/site-packages/sqlalchemy/engine/base.py", line 3315, in connect
    return self._connection_cls(self, close_with_result=close_with_result)
  File "/home/airflow/.local/lib/python3.7/site-packages/sqlalchemy/engine/base.py", line 96, in __init__
    else engine.raw_connection()
  File "/home/airflow/.local/lib/python3.7/site-packages/sqlalchemy/engine/base.py", line 3394, in raw_connection
    return self._wrap_pool_connect(self.pool.connect, _connection)
  File "/home/airflow/.local/lib/python3.7/site-packages/sqlalchemy/engine/base.py", line 3365, in _wrap_pool_connect
    e, dialect, self
  File "/home/airflow/.local/lib/python3.7/site-packages/sqlalchemy/engine/base.py", line 2199, in _handle_dbapi_exception_noconnection
    sqlalchemy_exception, with_traceback=exc_info[2], from_=e
  File "/home/airflow/.local/lib/python3.7/site-packages/sqlalchemy/util/compat.py", line 211, in raise_
    raise exception
  File "/home/airflow/.local/lib/python3.7/site-packages/sqlalchemy/engine/base.py", line 3361, in _wrap_pool_connect
    return fn()
  File "/home/airflow/.local/lib/python3.7/site-packages/sqlalchemy/pool/base.py", line 327, in connect
    return _ConnectionFairy._checkout(self)
  File "/home/airflow/.local/lib/python3.7/site-packages/sqlalchemy/pool/base.py", line 894, in _checkout
    fairy = _ConnectionRecord.checkout(pool)
  File "/home/airflow/.local/lib/python3.7/site-packages/sqlalchemy/pool/base.py", line 493, in checkout
    rec = pool._do_get()
  File "/home/airflow/.local/lib/python3.7/site-packages/sqlalchemy/pool/impl.py", line 146, in _do_get
    self._dec_overflow()
  File "/home/airflow/.local/lib/python3.7/site-packages/sqlalchemy/util/langhelpers.py", line 72, in __exit__
    with_traceback=exc_tb,
  File "/home/airflow/.local/lib/python3.7/site-packages/sqlalchemy/util/compat.py", line 211, in raise_
    raise exception
  File "/home/airflow/.local/lib/python3.7/site-packages/sqlalchemy/pool/impl.py", line 143, in _do_get
    return self._create_connection()
  File "/home/airflow/.local/lib/python3.7/site-packages/sqlalchemy/pool/base.py", line 273, in _create_connection
    return _ConnectionRecord(self)
  File "/home/airflow/.local/lib/python3.7/site-packages/sqlalchemy/pool/base.py", line 388, in __init__
    self.__connect()
  File "/home/airflow/.local/lib/python3.7/site-packages/sqlalchemy/pool/base.py", line 691, in __connect
    pool.logger.debug("Error on connect(): %s", e)
  File "/home/airflow/.local/lib/python3.7/site-packages/sqlalchemy/util/langhelpers.py", line 72, in __exit__
    with_traceback=exc_tb,
  File "/home/airflow/.local/lib/python3.7/site-packages/sqlalchemy/util/compat.py", line 211, in raise_
    raise exception
  File "/home/airflow/.local/lib/python3.7/site-packages/sqlalchemy/pool/base.py", line 686, in __connect
    self.dbapi_connection = connection = pool._invoke_creator(self)
  File "/home/airflow/.local/lib/python3.7/site-packages/sqlalchemy/engine/create.py", line 578, in connect
    return dialect.connect(*cargs, **cparams)
  File "/home/airflow/.local/lib/python3.7/site-packages/duckdb_engine/__init__.py", line 282, in connect
    conn = duckdb.connect(*cargs, **cparams)
sqlalchemy.exc.OperationalError: (duckdb.duckdb.IOException) IO Error: Could not set lock on file "/data/listenbrainz.duckdb": Conflicting lock is held in PID 0. See also https://duckdb.org/docs/connect/concurrency
(Background on this error at: https://sqlalche.me/e/14/e3q8)
[2025-02-21T14:24:15.434+0000] {taskinstance.py:1323} INFO - Marking task as UP_FOR_RETRY. dag_id=listenbrainz_dynamic_pipeline, task_id=create_schema, execution_date=20250101T000000, start_date=20250221T142415, end_date=20250221T142415
[2025-02-21T14:24:15.444+0000] {standard_task_runner.py:105} ERROR - Failed to execute job 3 for task create_schema ((duckdb.duckdb.IOException) IO Error: Could not set lock on file "/data/listenbrainz.duckdb": Conflicting lock is held in PID 0. See also https://duckdb.org/docs/connect/concurrency
(Background on this error at: https://sqlalche.me/e/14/e3q8); 185)
[2025-02-21T14:24:15.465+0000] {local_task_job.py:208} INFO - Task exited with return code 1
[2025-02-21T14:24:15.495+0000] {taskinstance.py:2578} INFO - 0 downstream tasks scheduled from follow-on schedule check
[2025-02-21T14:25:15.635+0000] {taskinstance.py:1083} INFO - Dependencies all met for <TaskInstance: listenbrainz_dynamic_pipeline.create_schema scheduled__2025-01-01T00:00:00+00:00 [queued]>
[2025-02-21T14:25:15.641+0000] {taskinstance.py:1083} INFO - Dependencies all met for <TaskInstance: listenbrainz_dynamic_pipeline.create_schema scheduled__2025-01-01T00:00:00+00:00 [queued]>
[2025-02-21T14:25:15.641+0000] {taskinstance.py:1279} INFO - 
--------------------------------------------------------------------------------
[2025-02-21T14:25:15.641+0000] {taskinstance.py:1280} INFO - Starting attempt 1 of 2
[2025-02-21T14:25:15.641+0000] {taskinstance.py:1281} INFO - 
--------------------------------------------------------------------------------
[2025-02-21T14:25:15.650+0000] {taskinstance.py:1300} INFO - Executing <Task(_PythonDecoratedOperator): create_schema> on 2025-01-01 00:00:00+00:00
[2025-02-21T14:25:15.654+0000] {standard_task_runner.py:55} INFO - Started process 227 to run task
[2025-02-21T14:25:15.655+0000] {standard_task_runner.py:82} INFO - Running: ['***', 'tasks', 'run', 'listenbrainz_dynamic_pipeline', 'create_schema', 'scheduled__2025-01-01T00:00:00+00:00', '--job-id', '4', '--raw', '--subdir', 'DAGS_FOLDER/listenbrainz_dag.py', '--cfg-path', '/tmp/tmp0k5dtf5o']
[2025-02-21T14:25:15.656+0000] {standard_task_runner.py:83} INFO - Job 4: Subtask create_schema
[2025-02-21T14:25:15.713+0000] {task_command.py:388} INFO - Running <TaskInstance: listenbrainz_dynamic_pipeline.create_schema scheduled__2025-01-01T00:00:00+00:00 [running]> on host 67bebaff4560
[2025-02-21T14:25:15.769+0000] {taskinstance.py:1509} INFO - Exporting the following env vars:
AIRFLOW_CTX_DAG_OWNER=***
AIRFLOW_CTX_DAG_ID=listenbrainz_dynamic_pipeline
AIRFLOW_CTX_TASK_ID=create_schema
AIRFLOW_CTX_EXECUTION_DATE=2025-01-01T00:00:00+00:00
AIRFLOW_CTX_TRY_NUMBER=1
AIRFLOW_CTX_DAG_RUN_ID=scheduled__2025-01-01T00:00:00+00:00
[2025-02-21T14:25:15.835+0000] {listenbrainz_dag.py:58} INFO - Schema created/ensured.
[2025-02-21T14:25:15.835+0000] {python.py:177} INFO - Done. Returned value was: None
[2025-02-21T14:25:15.844+0000] {taskinstance.py:1323} INFO - Marking task as SUCCESS. dag_id=listenbrainz_dynamic_pipeline, task_id=create_schema, execution_date=20250101T000000, start_date=20250221T142515, end_date=20250221T142515
[2025-02-21T14:25:15.867+0000] {local_task_job.py:208} INFO - Task exited with return code 0
[2025-02-21T14:25:15.897+0000] {taskinstance.py:2578} INFO - 1 downstream tasks scheduled from follow-on schedule check
