[2025-02-21T13:07:23.864+0000] {taskinstance.py:1083} INFO - Dependencies all met for <TaskInstance: listenbrainz_pipeline_duckdb.load_csv manual__2025-02-21T13:07:15.931035+00:00 [queued]>
[2025-02-21T13:07:23.870+0000] {taskinstance.py:1083} INFO - Dependencies all met for <TaskInstance: listenbrainz_pipeline_duckdb.load_csv manual__2025-02-21T13:07:15.931035+00:00 [queued]>
[2025-02-21T13:07:23.870+0000] {taskinstance.py:1279} INFO - 
--------------------------------------------------------------------------------
[2025-02-21T13:07:23.871+0000] {taskinstance.py:1280} INFO - Starting attempt 1 of 2
[2025-02-21T13:07:23.871+0000] {taskinstance.py:1281} INFO - 
--------------------------------------------------------------------------------
[2025-02-21T13:07:23.881+0000] {taskinstance.py:1300} INFO - Executing <Task(PythonOperator): load_csv> on 2025-02-21 13:07:15.931035+00:00
[2025-02-21T13:07:23.885+0000] {standard_task_runner.py:55} INFO - Started process 307 to run task
[2025-02-21T13:07:23.887+0000] {standard_task_runner.py:82} INFO - Running: ['***', 'tasks', 'run', 'listenbrainz_pipeline_duckdb', 'load_csv', 'manual__2025-02-21T13:07:15.931035+00:00', '--job-id', '6', '--raw', '--subdir', 'DAGS_FOLDER/listenbrainz_dag.py', '--cfg-path', '/tmp/tmp1cwqpkt2']
[2025-02-21T13:07:23.888+0000] {standard_task_runner.py:83} INFO - Job 6: Subtask load_csv
[2025-02-21T13:07:23.940+0000] {task_command.py:388} INFO - Running <TaskInstance: listenbrainz_pipeline_duckdb.load_csv manual__2025-02-21T13:07:15.931035+00:00 [running]> on host 74154169cff7
[2025-02-21T13:07:23.999+0000] {taskinstance.py:1509} INFO - Exporting the following env vars:
AIRFLOW_CTX_DAG_OWNER=***
AIRFLOW_CTX_DAG_ID=listenbrainz_pipeline_duckdb
AIRFLOW_CTX_TASK_ID=load_csv
AIRFLOW_CTX_EXECUTION_DATE=2025-02-21T13:07:15.931035+00:00
AIRFLOW_CTX_TRY_NUMBER=1
AIRFLOW_CTX_DAG_RUN_ID=manual__2025-02-21T13:07:15.931035+00:00
[2025-02-21T13:07:24.301+0000] {logging_mixin.py:137} WARNING - /home/***/.local/lib/python3.7/site-packages/pandas/io/sql.py:1809 SAWarning: Did not recognize type 'varchar' of column 'user_id'
[2025-02-21T13:07:24.301+0000] {logging_mixin.py:137} WARNING - /home/***/.local/lib/python3.7/site-packages/pandas/io/sql.py:1809 SAWarning: Did not recognize type 'varchar' of column 'track_id'
[2025-02-21T13:07:24.302+0000] {logging_mixin.py:137} WARNING - /home/***/.local/lib/python3.7/site-packages/pandas/io/sql.py:1809 SAWarning: Did not recognize type 'varchar' of column 'track_name'
[2025-02-21T13:07:24.302+0000] {logging_mixin.py:137} WARNING - /home/***/.local/lib/python3.7/site-packages/pandas/io/sql.py:1809 SAWarning: Did not recognize type 'varchar' of column 'artist_name'
[2025-02-21T13:07:24.318+0000] {logging_mixin.py:137} WARNING - /home/***/.local/lib/python3.7/site-packages/duckdb_engine/__init__.py:183 DuckDBEngineWarning: duckdb-engine doesn't yet support reflection on indices
[2025-02-21T13:07:24.353+0000] {taskinstance.py:1768} ERROR - Task failed with exception
Traceback (most recent call last):
  File "/home/airflow/.local/lib/python3.7/site-packages/sqlalchemy/engine/base.py", line 1089, in _commit_impl
    self.engine.dialect.do_commit(self.connection)
  File "/home/airflow/.local/lib/python3.7/site-packages/sqlalchemy/engine/default.py", line 686, in do_commit
    dbapi_connection.commit()
duckdb.duckdb.TransactionException: TransactionContext Error: Failed to commit: Cannot open file "/data/listenbrainz.duckdb.wal": Permission denied

The above exception was the direct cause of the following exception:

Traceback (most recent call last):
  File "/home/airflow/.local/lib/python3.7/site-packages/airflow/operators/python.py", line 175, in execute
    return_value = self.execute_callable()
  File "/home/airflow/.local/lib/python3.7/site-packages/airflow/operators/python.py", line 192, in execute_callable
    return self.python_callable(*self.op_args, **self.op_kwargs)
  File "/opt/airflow/dags/listenbrainz_dag.py", line 72, in load_csv
    load_csv_to_stg(engine, LISTENS_CSV_PATH, "stg_listens", chunksize=50000)
  File "/opt/airflow/src/pipeline/unified_pipeline.py", line 121, in load_csv_to_stg
    chunk.to_sql(stg_table, db_engine, if_exists='replace', index=False)
  File "/home/airflow/.local/lib/python3.7/site-packages/pandas/core/generic.py", line 2882, in to_sql
    method=method,
  File "/home/airflow/.local/lib/python3.7/site-packages/pandas/io/sql.py", line 728, in to_sql
    **engine_kwargs,
  File "/home/airflow/.local/lib/python3.7/site-packages/pandas/io/sql.py", line 1758, in to_sql
    dtype=dtype,
  File "/home/airflow/.local/lib/python3.7/site-packages/pandas/io/sql.py", line 1650, in prep_table
    table.create()
  File "/home/airflow/.local/lib/python3.7/site-packages/pandas/io/sql.py", line 860, in create
    self.pd_sql.drop_table(self.name, self.schema)
  File "/home/airflow/.local/lib/python3.7/site-packages/pandas/io/sql.py", line 1810, in drop_table
    self.get_table(table_name, schema).drop()
  File "/home/airflow/.local/lib/python3.7/site-packages/sqlalchemy/sql/schema.py", line 979, in drop
    bind._run_ddl_visitor(ddl.SchemaDropper, self, checkfirst=checkfirst)
  File "/home/airflow/.local/lib/python3.7/site-packages/sqlalchemy/future/engine.py", line 342, in _run_ddl_visitor
    conn._run_ddl_visitor(visitorcallable, element, **kwargs)
  File "/usr/local/lib/python3.7/contextlib.py", line 119, in __exit__
    next(self.gen)
  File "/home/airflow/.local/lib/python3.7/site-packages/sqlalchemy/future/engine.py", line 381, in begin
    yield conn
  File "/home/airflow/.local/lib/python3.7/site-packages/sqlalchemy/engine/util.py", line 237, in __exit__
    self.rollback()
  File "/home/airflow/.local/lib/python3.7/site-packages/sqlalchemy/util/langhelpers.py", line 72, in __exit__
    with_traceback=exc_tb,
  File "/home/airflow/.local/lib/python3.7/site-packages/sqlalchemy/util/compat.py", line 211, in raise_
    raise exception
  File "/home/airflow/.local/lib/python3.7/site-packages/sqlalchemy/engine/util.py", line 233, in __exit__
    self.commit()
  File "/home/airflow/.local/lib/python3.7/site-packages/sqlalchemy/engine/base.py", line 2459, in commit
    self._do_commit()
  File "/home/airflow/.local/lib/python3.7/site-packages/sqlalchemy/engine/base.py", line 2649, in _do_commit
    self._connection_commit_impl()
  File "/home/airflow/.local/lib/python3.7/site-packages/sqlalchemy/engine/base.py", line 2620, in _connection_commit_impl
    self.connection._commit_impl()
  File "/home/airflow/.local/lib/python3.7/site-packages/sqlalchemy/engine/base.py", line 1091, in _commit_impl
    self._handle_dbapi_exception(e, None, None, None, None)
  File "/home/airflow/.local/lib/python3.7/site-packages/sqlalchemy/engine/base.py", line 2125, in _handle_dbapi_exception
    sqlalchemy_exception, with_traceback=exc_info[2], from_=e
  File "/home/airflow/.local/lib/python3.7/site-packages/sqlalchemy/util/compat.py", line 211, in raise_
    raise exception
  File "/home/airflow/.local/lib/python3.7/site-packages/sqlalchemy/engine/base.py", line 1089, in _commit_impl
    self.engine.dialect.do_commit(self.connection)
  File "/home/airflow/.local/lib/python3.7/site-packages/sqlalchemy/engine/default.py", line 686, in do_commit
    dbapi_connection.commit()
sqlalchemy.exc.OperationalError: (duckdb.duckdb.TransactionException) TransactionContext Error: Failed to commit: Cannot open file "/data/listenbrainz.duckdb.wal": Permission denied
(Background on this error at: https://sqlalche.me/e/14/e3q8)
[2025-02-21T13:07:24.367+0000] {taskinstance.py:1323} INFO - Marking task as UP_FOR_RETRY. dag_id=listenbrainz_pipeline_duckdb, task_id=load_csv, execution_date=20250221T130715, start_date=20250221T130723, end_date=20250221T130724
[2025-02-21T13:07:24.375+0000] {standard_task_runner.py:105} ERROR - Failed to execute job 6 for task load_csv ((duckdb.duckdb.TransactionException) TransactionContext Error: Failed to commit: Cannot open file "/data/listenbrainz.duckdb.wal": Permission denied
(Background on this error at: https://sqlalche.me/e/14/e3q8); 307)
[2025-02-21T13:07:24.419+0000] {local_task_job.py:208} INFO - Task exited with return code 1
[2025-02-21T13:07:24.444+0000] {taskinstance.py:2578} INFO - 0 downstream tasks scheduled from follow-on schedule check
